<?xml version="1.0"?>
<robot name="phantomx_reactor" xmlns:xacro="http://www.ros.org/wiki/xacro">

	<xacro:property name="PI" value="3.141593"/>
	<xacro:property name="joint_1_upper_limit" value="${PI}"/>
	<xacro:property name="joint_1_lower_limit" value="-${PI}"/>
	<xacro:property name="joint_2_upper_limit" value="${PI/2}"/>
	<xacro:property name="joint_2_lower_limit" value="-${PI/2}"/>
	<xacro:property name="joint_3_upper_limit" value="1.8"/>
	<xacro:property name="joint_3_lower_limit" value="-1.0"/>
	<xacro:property name="joint_4_upper_limit" value="${PI/2}"/>
	<xacro:property name="joint_4_lower_limit" value="-${PI/2}"/>
	
	
	<xacro:macro name="phantomx_reactor_4dof" params="parent name *origin">
		
		<link name="${name}_base_link">
			<inertial>
			  <origin xyz="-3.9657E-09 2.0144E-09 0.04262" rpy="0 0 0" />
			  <mass value="0.33742" />
			  <inertia ixx="0.0011303" ixy="2.3398E-15" ixz="5.3844E-11"
				iyy="0.0011303" iyz="-2.735E-11" izz="0.0016747" />
			</inertial>
			<visual>
			  <origin
				xyz="0 0 0"
				rpy="0 0 0" />
			  <geometry>
				<mesh
				  filename="package://phantomx_reactor_arm_description/meshes/base_link.STL" />
			  </geometry>
			  <material
				name="">
				<color
				  rgba="0.25098 0.25098 0.25098 1" />
			  </material>
			</visual>
			<collision>
			  <origin
				xyz="0 0 0"
				rpy="0 0 0" />
			  <geometry>
				<mesh
				  filename="package://phantomx_reactor_arm_description/meshes/base_link_hull.STL" />
			  </geometry>
			</collision>
		</link>
		
		<joint name="${name}_base_joint" type="fixed">
			<insert_block name="origin" />
			
			<parent
			  link="${parent}" />
			<child
			  link="${name}_base_link" />
		</joint>
		
		<!-- JOINT 1 -->
		<link name="${name}_1_link">
			<inertial>
			  <origin
				xyz="5.5296E-07 0.00048339 0.0026355"
				rpy="0 0 0" />
			  <mass
				value="0.069055" />
			  <inertia
				ixx="7.786E-05"
				ixy="4.5909E-11"
				ixz="-6.4873E-11"
				iyy="4.1745E-05"
				iyz="2.8244E-07"
				izz="0.0001073" />
			</inertial>
			<visual>
			  <origin
				xyz="0 0 0"
				rpy="0 0 0" />
			  <geometry>
				<mesh
				  filename="package://phantomx_reactor_arm_description/meshes/shoulder_link.STL" />
			  </geometry>
			  <material
				name="">
				<color
				  rgba="0.25098 0.25098 0.25098 1" />
			  </material>
			</visual>
			<collision>
			  <origin
				xyz="0 0 0"
				rpy="0 0 0" />
			  <geometry>
				<mesh
				  filename="package://phantomx_reactor_arm_description/meshes/shoulder_link_hull.STL" />
			  </geometry>
			</collision>
		</link>
		
		<joint name="${name}_1_joint" type="revolute">
			<origin
			  xyz="0 0 0.081"
			  rpy="0 0 0" />
			<parent
			  link="${name}_base_link" />
			<child
			  link="${name}_1_link" />
			<axis
			  xyz="0 0 1" />
			<limit
			  effort="1.5"
			  velocity="6.178465545" 
			  lower="-3.141593"
			  upper="3.141593" />
		</joint>
		
		<!-- JOINT 2 -->
		<link name="${name}_2_link">
			<inertial>
			  <origin
				xyz="-0.079312 0.00175 0.0073486"
				rpy="-${PI/2} 0 -${PI/2}" />
			  <mass
				value="0.29331" />
			  <inertia
				ixx="0.00040741"
				ixy="-1.1578E-09"
				ixz="-0.00014106"
				iyy="0.0010604"
				iyz="1.1578E-09"
				izz="0.0012838" />
			</inertial>
			<visual>
			  <origin
				xyz="0 0 0"
				rpy="-${PI/2} 0 -${PI/2}" />
			  <geometry>
				<mesh
				  filename="package://phantomx_reactor_arm_description/meshes/bicep_link.STL" />
			  </geometry>
			  <material
				name="">
				<color
				  rgba="0.25098 0.25098 0.25098 1" />
			  </material>
			</visual>
			<collision>
			  <origin
				xyz="0 0 0"
				rpy="-${PI/2} 0 -${PI/2}" />
			  <geometry>
				<mesh
				  filename="package://phantomx_reactor_arm_description/meshes/bicep_link_hull.STL" />
			  </geometry>
			</collision>
	  </link>
	  
	  <joint name="${name}_2_joint" type="revolute">
		<origin xyz="0 0 0.0265" rpy="${PI/2} 0 0" />
		<parent link="${name}_1_link" />
		<child link="${name}_2_link" />
		<axis xyz="0 0 -1" />
		<limit
		  effort="3.0"
		  velocity="6.178465545" 
		  lower="${joint_2_lower_limit}"
		  upper="${joint_2_upper_limit}" />
	  </joint>
	  
	  <!-- JOINT 3 -->
	  <link name="${name}_3_link">
		<inertial>
		  <origin
			xyz="0.0851888339312843 0.00136288621406396 -0.000141576344087929"
			rpy="-${PI/2} 0 0" />
		  <mass
			value="0.138705662443181" />
		  <inertia
				ixx="9.73074886909647E-05"
				ixy="-2.7259894490049E-06"
				ixz="8.2757647661483E-07"
				iyy="0.000291190570207828"
				iyz="-7.99252279784603E-09"
				izz="0.000367301178753318" />
		</inertial>
		<visual>
		  <origin
			xyz="0 0 0"
			rpy="-${PI/2} 0 0" />
		  <geometry>
			<mesh
			  filename="package://phantomx_reactor_arm_description/meshes/forearm_link.STL" />
		  </geometry>
		  <material
			name="">
			<color
			  rgba="0.25098 0.25098 0.25098 1" />
		  </material>
		</visual>
		<collision>
		  <origin
			xyz="0 0 0"
			rpy="-${PI/2} 0 0" />
		  <geometry>
			<mesh
			  filename="package://phantomx_reactor_arm_description/meshes/forearm_link_hull.STL" />
		  </geometry>
		</collision>
	  </link>
	  
	  <joint name="${name}_3_joint"	type="revolute">
		<origin xyz="0.0385 0.1445 0.0" rpy="0 0 0" />
		<parent link="${name}_2_link" />
		<child link="${name}_3_link" />
		<axis xyz="0 0 1" />
		<limit
		  effort="3.0"
		  velocity="6.178465545" 
		  lower="${joint_3_lower_limit}"
		  upper="${joint_3_upper_limit}"/>
	  </joint>
	  
	  
	  <link name="${name}_4_link">
		<inertial>
		  <origin
			xyz="0.0426453655090486 0.0017494960392062 0.00984847105297723"
			rpy="-${PI/2} 0 0" />
		  <mass
			value="0.0605067986491363" />
		  <inertia
			ixx="1.78648656995261E-05"
			ixy="1.11621731933541E-10"
			ixz="3.58888722407994E-06"
			iyy="2.8352036542644E-05"
			iyz="-2.18072661043818E-10"
			izz="2.38673851634115E-05" />
		</inertial>
		<visual>
		  <origin
			xyz="0 0 0"
			rpy="-${PI/2} 0 0" />
		  <geometry>
			<mesh
			  filename="package://phantomx_reactor_arm_description/meshes/wrist_1.STL" />
		  </geometry>
		  <material
			name="">
			<color
			  rgba="0.25098 0.25098 0.25098 1" />
		  </material>
		</visual>
		<collision>
		  <origin
			xyz="0 0 0"
			rpy="-${PI/2} 0 0" />
		  <geometry>
			<mesh
			  filename="package://phantomx_reactor_arm_description/meshes/wrist_1_hull.STL" />
		  </geometry>
		</collision>
	  </link>
	  
	  <joint name="${name}_4_joint"	type="revolute">
		<origin
		  xyz="0.1535 0 0"
		  rpy="0 0 0" />
		<parent
		  link="${name}_3_link" />
		<child
		  link="${name}_4_link" />
		<axis
		  xyz="0 0 1" />
		<limit
		  effort="1.5"
		  velocity="6.178465545" 
		  lower="${joint_4_lower_limit}"
		  upper="${joint_4_upper_limit}" />
	  </joint>
	  
	  <link name="${name}_gripper_link">
		<inertial>
		  <origin
			xyz="0.0091884 -7.3309E-13 -3.4513E-05"
			rpy="0 0 0" />
		  <mass
			value="0.02487" />
		  <inertia
			ixx="1.5997E-05"
			ixy="1.6551E-16"
			ixz="8.3911E-09"
			iyy="7.3918E-06"
			iyz="-2.7145E-16"
			izz="1.5931E-05" />
		</inertial>
		<visual>
		  <origin
			xyz="0 0 0"
			rpy="0 0 0" />
		  <geometry>
			<mesh
			  filename="package://phantomx_reactor_arm_description/meshes/gripper_link.STL" />
		  </geometry>
		  <material
			name="">
			<color
			  rgba="0.25098 0.25098 0.25098 1" />
		  </material>
		</visual>
		<collision>
		  <origin
			xyz="0 0 0"
			rpy="0 0 0" />
		  <geometry>
			<mesh
			  filename="package://phantomx_reactor_arm_description/meshes/gripper_link_hull.STL" />
		  </geometry>
		</collision>
	  </link>
	  
	  <joint name="${name}_gripper_joint" type="fixed">
		<origin
		  xyz="0.07289 0.00175 0"
		  rpy="${PI/2} 0 0" />
		<parent
		  link="${name}_4_link" />
		<child
		  link="${name}_gripper_link" />
		<axis
		  xyz="0 0 0" />
	  </joint>
	  <!--
	  
	  
	  
	   
	  <link	name="wrist_2">
		<inertial>
		  <origin
			xyz="0.022349 -5.4754E-07 0.0089164"
			rpy="0 0 0" />
		  <mass
			value="0.055706" />
		  <inertia
			ixx="1.5957E-05"
			ixy="2.0952E-10"
			ixz="3.3629E-06"
			iyy="2.1196E-05"
			iyz="-2.4643E-10"
			izz="1.4482E-05" />
		</inertial>
		<visual>
		  <origin
			xyz="0 0 0"
			rpy="0 0 0" />
		  <geometry>
			<mesh
			  filename="package://phantomx_reactor_arm_description/meshes/wrist_2.STL" />
		  </geometry>
		  <material
			name="">
			<color
			  rgba="0.25098 0.25098 0.25098 1" />
		  </material>
		</visual>
		<collision>
		  <origin
			xyz="0 0 0"
			rpy="0 0 0" />
		  <geometry>
			<mesh
			  filename="package://phantomx_reactor_arm_description/meshes/wrist_2_hull.STL" />
		  </geometry>
		</collision>
	  </link>
	  
	  <joint name="wrist_roll"type="revolute">
		<origin
		  xyz="0.071 0.00175 0"
		  rpy="0 0 0" />
		<parent
		  link="wrist_1" />
		<child
		  link="wrist_2" />
		<axis
		  xyz="1 0 0" />
		<limit
		  effort="1.5"
		  velocity="6.178465545" 
		  lower="-3.141593"
		  upper="3.141593" />
	  </joint>
	  
	  <link name="gripper_link">
		<inertial>
		  <origin
			xyz="0.0091884 -7.3309E-13 -3.4513E-05"
			rpy="0 0 0" />
		  <mass
			value="0.02487" />
		  <inertia
			ixx="1.5997E-05"
			ixy="1.6551E-16"
			ixz="8.3911E-09"
			iyy="7.3918E-06"
			iyz="-2.7145E-16"
			izz="1.5931E-05" />
		</inertial>
		<visual>
		  <origin
			xyz="0 0 0"
			rpy="0 0 0" />
		  <geometry>
			<mesh
			  filename="package://phantomx_reactor_arm_description/meshes/gripper_link.STL" />
		  </geometry>
		  <material
			name="">
			<color
			  rgba="0.25098 0.25098 0.25098 1" />
		  </material>
		</visual>
		<collision>
		  <origin
			xyz="0 0 0"
			rpy="0 0 0" />
		  <geometry>
			<mesh
			  filename="package://phantomx_reactor_arm_description/meshes/gripper_link_hull.STL" />
		  </geometry>
		</collision>
	  </link>
	  
	  <joint name="gripper_joint" type="fixed">
		<origin
		  xyz="0.04789 0 0"
		  rpy="0 0 0" />
		<parent
		  link="wrist_2" />
		<child
		  link="gripper_link" />
		<axis
		  xyz="0 0 0" />
	  </joint>
	  -->
	  
	</xacro:macro>

</robot>
